<?xml version="1.0"?>
<sdf version="1.6">
    <model name="rmf_owl">
        <pose>0 0 0 0 0 0</pose>

        <frame name="rmf_owl" attached_to='base_link'>
            <pose>0 0 0 0 0 0</pose>
        </frame>

        <link name="base_link">
            <pose frame="">0 0 0 0 -0 0</pose>
            <inertial>
                <pose frame="">0 0 0 0 -0 0</pose>
                <mass>1.46</mass> <!--4.10-->
                <inertia>
                    <ixx>0.017</ixx>
                    <ixy>0</ixy>
                    <ixz>0</ixz>
                    <iyy>0.018</iyy>
                    <iyz>0</iyz>
                    <izz>0.028</izz>
                </inertia>
            </inertial>
            <collision name="base_link_inertia_collision">
                <pose frame="">0 0 0 0 -0 0</pose>
                <geometry>
                    <mesh>
                        <scale>1 1 1</scale>
                        <uri>meshes/rmf_owl.dae</uri>
                    </mesh>
                </geometry>
            </collision>
            <visual name="base_link_inertia_visual">
                <pose frame="">0 0 0 0 -0 0</pose>
                <geometry>
                    <mesh>
                        <scale>1 1 1</scale>
                        <uri>meshes/rmf_owl.dae</uri>
                    </mesh>
                </geometry>
            </visual>

            <!--Outlook of realsense_d435i/d455-->
            <collision name="realsense_visual">
                <pose frame="">0.0285 0 0.0328 0 -0 1.57</pose>
                <geometry>
                    <mesh>
                        <scale>1 1 1</scale>
                        <uri>meshes/realsense.dae</uri>
                    </mesh>
                </geometry>
            </collision>
            <visual name="realsense_visual">
                <pose frame="">0.04 0 0.036 0 -0 1.57</pose>
                <geometry>
                    <mesh>
                        <scale>1 1 1</scale>
                        <uri>meshes/realsense.dae</uri>
                    </mesh>
                </geometry>
            </visual>

            <!--IMU of realsense-->
            <sensor name="imu_sensor" type="imu">
                <!--<pose>0.0 0.0 0.0 1.5708 0 1.5708</pose>-->
                <pose>0.0 0.0 0.0 0 0 0</pose>
                <always_on>1</always_on>
                <update_rate>200</update_rate>
                <imu>
                    <!--              
                    <orientation_reference_frame>
                        <localization>WUN</localization>
                        <custom_rpy parent_frame="rmf_owl">1.5708 0 1.5708</custom_rpy>
                        <gravity_dir_x parent_frame="rmf_owl">1 0 0</gravity_dir_x>
                    </orientation_reference_frame>
                    -->                    
                    <!--
                        <mean> and <std> are parameters of Gaussian noise
                        <bias_mean> and <bias_stddev> are parameters of Gaussian bias
                        <dynamic_bias_stddev> and <dynamic_bias_correlation_time> are parameters of noise, which drives slow derivation of sensor bias
                        <precision> is the precision of Gaussian quantized output signal
                    -->
                    <angular_velocity>
                        <x>
                            <noise type="gaussian">
                                <mean>0</mean>
                                <stddev>0.00</stddev>
                                <bias_mean>0.00</bias_mean>
                                <bias_stddev>0.00</bias_stddev>
                                <dynamic_bias_stddev>0.00</dynamic_bias_stddev>
                                <dynamic_bias_correlation_time>400.0</dynamic_bias_correlation_time>
                                <precision>0.00</precision>
                            </noise>
                        </x>
                        <y>
                            <noise type="gaussian">
                                <mean>0</mean>
                                <stddev>0.00</stddev>
                                <bias_mean>0.00</bias_mean>
                                <bias_stddev>0.00</bias_stddev>
                                <dynamic_bias_stddev>0.00</dynamic_bias_stddev>
                                <dynamic_bias_correlation_time>400.0</dynamic_bias_correlation_time>
                                <precision>0.00</precision>
                            </noise>
                        </y>
                        <z>
                            <noise type="gaussian">
                                <mean>0</mean>
                                <stddev>0.00</stddev>
                                <bias_mean>0.00</bias_mean>
                                <bias_stddev>0.00</bias_stddev>
                                <dynamic_bias_stddev>0.00</dynamic_bias_stddev>
                                <dynamic_bias_correlation_time>400.0</dynamic_bias_correlation_time>
                                <precision>0.00</precision>
                            </noise>
                        </z>
                    </angular_velocity>
                    <linear_acceleration>
                        <x>
                            <noise type="gaussian">
                                <mean>0.0</mean>
                                <stddev>0.00</stddev>
                                <bias_mean>0.0</bias_mean>
                                <bias_stddev>0.00</bias_stddev>
                                <dynamic_bias_stddev>0.00</dynamic_bias_stddev>
                                <dynamic_bias_correlation_time>175.0</dynamic_bias_correlation_time>
                                <precision>0.00</precision>
                            </noise>
                        </x>
                        <y>
                            <noise type="gaussian">
                                <mean>0.0</mean>
                                <stddev>0.00</stddev>
                                <bias_mean>0.0</bias_mean>
                                <bias_stddev>0.00</bias_stddev>
                                <dynamic_bias_stddev>0.00</dynamic_bias_stddev>
                                <dynamic_bias_correlation_time>175.0</dynamic_bias_correlation_time>
                                <precision>0.00</precision>
                            </noise>
                        </y>
                        <z>
                            <noise type="gaussian">
                                <mean>0.0</mean>
                                <stddev>0.00</stddev>
                                <bias_mean>0.0</bias_mean>
                                <bias_stddev>0.00</bias_stddev>
                                <dynamic_bias_stddev>0.00</dynamic_bias_stddev>
                                <dynamic_bias_correlation_time>175.0</dynamic_bias_correlation_time>
                                <precision>0.00</precision>
                            </noise>
                        </z>
                    </linear_acceleration>
                </imu>
            </sensor>

            <!--Left camera of realsense-->
            <sensor name="camera_left" type="camera">
                <!--<pose>0.18 0 0.0328 0 -0 0</pose>--> <!--realsense's postion on rmf_owl-->
                <!--<pose>0.0074000000 -0.0302200001 0.0160200000 0 -0 0</pose>--> <!--realsense's pose from config file-->
                <!--<pose>0.1874000000 -0.0302200001 0.0488200000 0 -0 0</pose>--> <!--integration of both-->
                <pose>0.2 0.0475 0.2 0 0 0</pose>
                <!--<pose>0.0 0.4 0.2 0 0 0</pose>-->
                <!--<pose>0.0 0.5 0.0 -1.5708 0 -1.5708</pose>-->
                <always_on>1</always_on>
                <update_rate>15</update_rate>
                <visualize>true</visualize>
                <camera name="camera_left">
                    <!--
                        calculation of horizontal_fov:
                        h_fov = 2*tan-1(width/(2*fx))
                    -->
                    <horizontal_fov>1.37274</horizontal_fov>
                    <lens>
                        <intrinsics>
                            <fx>390.598938</fx>
                            <fy>390.598938</fy>
                            <cx>320.581665</cx>
                            <cy>237.712845</cy>
                            <s>0</s>
                        </intrinsics>
                    </lens>
                    <distortion>
                        <k1>0.0</k1>
                        <k2>0.0</k2>
                        <k3>0.0</k3>
                        <p1>0.0</p1>
                        <p2>0.0</p2>
                        <center>0.5 0.5</center>
                    </distortion>
                    <image>
                        <width>640</width>
                        <height>480</height>
                        <format>L8</format>
                    </image>
                    <!--
                    <clip>
                        <near>0.02</near>
                        <far>20</far>
                    </clip>
                    -->
                    <noise>
                        <type>gaussian</type>
                        <mean>0</mean>
                        <stddev>0.007</stddev>
                    </noise>
                </camera>
            </sensor>

            <!--Right camera of realsense-->
            <sensor name="camera_right" type="camera">
                <!--<pose>0.18 0 0.0328 0 -0 0</pose>--> <!--realsense's postion on rmf_owl-->
                <!--<pose>0.0074000000 0.0646901205 0.0160200000 0 -0 0</pose>--> <!--realsense's pose from config file-->
                <!--<pose>0.1874000000 0.0646901205 0.0488200000 0 -0 0</pose>--> <!--integration of both-->
                <pose>0.2 -0.0475 0.2 0 0 0</pose>
                <!--<pose>0.0 -0.4 0.2 0 0 0</pose>-->
                <!--<pose>0.0 -0.5 0.0 -1.5708 0 -1.5708</pose>-->
                <always_on>1</always_on>
                <update_rate>15</update_rate>
                <visualize>true</visualize>
                <camera name="camera_right">
                    <!--
                        calculation of horizontal_fov:
                        h_fov = 2*tan-1(width/(2*fx))
                    -->
                    <horizontal_fov>1.37274</horizontal_fov>
                    <lens>
                        <intrinsics>
                            <fx>390.598938</fx>
                            <fy>390.598938</fy>
                            <cx>320.581665</cx>
                            <cy>237.712845</cy>
                            <s>0</s>
                        </intrinsics>
                    </lens>
                    <distortion>
                        <k1>0.0</k1>
                        <k2>0.0</k2>
                        <k3>0.0</k3>
                        <p1>0.0</p1>
                        <p2>0.0</p2>
                        <center>0.5 0.5</center>
                    </distortion>
                    <image>
                        <width>640</width>
                        <height>480</height>
                        <format>L8</format>
                    </image>
                    <!--
                    <clip>
                        <near>0.02</near>
                        <far>20</far>
                    </clip>
                    -->
                    <noise>
                        <type>gaussian</type>
                        <mean>0</mean>
                        <stddev>0.007</stddev>
                    </noise>
                </camera>
            </sensor>

            <!--RGBD camera of realsense-->
            <!--
            <sensor name="camera_RGBD" type="camera">
                <pose>0.18 0 0.0328 0 -0 0</pose>
                <always_on>1</always_on>
                <update_rate>15</update_rate>
                <visualize>true</visualize>
                <camera name="camera_RGBD">
                    <horizontal_fov>2.0944</horizontal_fov>
                    <lens>
                        <intrinsics>
                            <fx>1108.952913</fx>
                            <fy>1110.658360</fy>
                            <cx>729.533992</cx>
                            <cy>544.985715</cy>
                            <s>1</s>
                        </intrinsics>
                    </lens>
                    <distortion>
                        <k1>0.0</k1>
                        <k2>0.0</k2>
                        <k3>0.0</k3>
                        <p1>0.0</p1>
                        <p2>0.0</p2>
                        <center>0.5 0.5</center>
                    </distortion>
                    <image>
                        <width>1440</width>
                        <height>1080</height>
                        <format>R8G8B8</format>
                    </image>
                    <clip>
                        <near>0.02</near>
                        <far>20</far>
                    </clip>
                    <noise>
                        <type>gaussian</type>
                        <mean>0</mean>
                        <stddev>0.007</stddev>
                    </noise>
                </camera>
            </sensor>
            
            
            <sensor name="depth_RGBD" type="depth_camera">
                <update_rate>15</update_rate>
                <pose>0.18 0 0.0328 0 -0 0</pose>
                <camera name="depth_RGBD">
                    <horizontal_fov>2.09</horizontal_fov>
                    <image>
                        <width>160</width>
                        <height>60</height>
                        <format>R_FLOAT32</format>
                    </image>
                    <clip>
                        <near>0.2</near>
                        <far>20.0</far>
                    </clip>
                    <noise>
                        <type>gaussian</type>
                        <mean>0</mean>
                        <stddev>0.00000000000000000001</stddev>
                    </noise>
                </camera>
            </sensor>-->
            

            <!--RGBD test-->
            <!--
            <sensor name="RGBD_test" type="rgbd_camera">
                <update_rate>20</update_rate>
                <pose>0 0 -0.025 0 0 0</pose>
                <camera name="RGBD_test">
                    <horizontal_fov>2.09</horizontal_fov>
                    <image>
                        <width>160</width>
                        <height>60</height>
                        <format>R_FLOAT32</format>
                    </image>
                    <clip>
                        <near>0.2</near>
                        <far>20.0</far>
                    </clip>
                    <noise>
                        <type>gaussian</type>
                        <mean>0</mean>
                        <stddev>0.00000000000000000001</stddev>
                    </noise>
                </camera>
            </sensor>
            -->

            <!--Outlook of LiDAR-->
            
            <visual name="laser_visual">
                <pose>0 0 0.05 0 0 0</pose>
                <geometry>
                    <cylinder>
                        <radius>0.03</radius>
                        <length>0.1</length>
                    </cylinder>
                </geometry>
            </visual>
            

            <!--LiDAR-->
            
            <sensor name="front_laser" type="gpu_ray">
                <pose>0 0 0.05 0 0 0</pose>
                <update_rate>3</update_rate>
                <visualize>true</visualize>
                <always_on>true</always_on>
                <ray>
                    <scan>
                        <horizontal>
                            <samples>1469</samples>
                            <resolution>1</resolution>
                            <min_angle>0</min_angle>
                            <max_angle>3.1459</max_angle>
                        </horizontal>
                        <vertical>
                            <samples>34</samples>
                            <resolution>1</resolution>
                            <min_angle>0</min_angle>
                            <max_angle>3.1459</max_angle>
                        </vertical>
                    </scan>
                    <range>
                        <min>0.8</min>
                        <max>30</max> <!--Extracted from Simon dataset-->
                        <resolution>0.01</resolution>
                    </range>
                    <noise>
                        <type>gaussian</type>
                        <mean>0</mean>
                        <stddev>0.03</stddev>
                    </noise>
                </ray>
            </sensor>

        </link>

        <link name="rotor_0">
            <pose frame="">0.09 -0.09 -0.005 0 0 0</pose>
            <inertial>
                <pose frame="">0 0 0 0 -0 0</pose>
                <mass>0.005</mass>
                <inertia>
                    <ixx>9.75e-07</ixx>
                    <ixy>0</ixy>
                    <ixz>0</ixz>
                    <iyy>8.13545e-05</iyy>
                    <iyz>0</iyz>
                    <izz>8.22545e-05</izz>
                </inertia>
            </inertial>
            <collision name="rotor_0_collision">
                <pose frame="">0 0 0 0 -0 0</pose>
                <geometry>
                    <cylinder>
                        <length>0.005</length>
                        <radius>0.06</radius>
                    </cylinder>
                </geometry>
                <surface>
                    <contact>
                        <ode />
                    </contact>
                    <friction>
                        <ode />
                    </friction>
                </surface>
            </collision>
            <visual name="rotor_0_visual">
                <pose frame="">0 0 0 0 -0 0</pose>
                <geometry>
                    <mesh>
                        <scale>1 1 1</scale>
                        <uri>meshes/propeller_ccw.dae</uri>
                    </mesh>
                </geometry>
                <material>
                    <diffuse>1 0 0 1</diffuse>
                    <script>
                        <name>Gazebo/Red</name>
                        <uri>file://media/materials/scripts/gazebo.material</uri>
                    </script>
                </material>
                <cast_shadows>0</cast_shadows>
            </visual>
            <gravity>1</gravity>
            <velocity_decay />
        </link>
        <joint name="rotor_0_joint" type="revolute">
            <child>rotor_0</child>
            <parent>base_link</parent>
            <axis>
                <xyz>0 0 1</xyz>
                <limit>
                    <lower>-1e+16</lower>
                    <upper>1e+16</upper>
                </limit>
                <dynamics>
                    <spring_reference>0</spring_reference>
                    <spring_stiffness>0</spring_stiffness>
                </dynamics>
                <use_parent_model_frame>1</use_parent_model_frame>
            </axis>
        </joint>


        <link name="rotor_1">
            <pose frame="">-0.09 0.09 0.045 0 0 0</pose>
            <inertial>
                <pose frame="">0 0 0 0 -0 0</pose>
                <mass>0.005</mass>
                <inertia>
                    <ixx>9.75e-07</ixx>
                    <ixy>0</ixy>
                    <ixz>0</ixz>
                    <iyy>8.13545e-05</iyy>
                    <iyz>0</iyz>
                    <izz>8.22545e-05</izz>
                </inertia>
            </inertial>
            <collision name="rotor_1_collision">
                <pose frame="">0 0 0 0 -0 0</pose>
                <geometry>
                    <cylinder>
                        <length>0.005</length>
                        <radius>0.06</radius>
                    </cylinder>
                </geometry>
                <surface>
                    <contact>
                        <ode />
                    </contact>
                    <friction>
                        <ode />
                    </friction>
                </surface>
            </collision>
            <visual name="rotor_1_visual">
                <pose frame="">0 0 0 0 -0 0</pose>
                <geometry>
                    <mesh>
                        <scale>1 1 1</scale>
                        <uri>meshes/propeller_ccw.dae</uri>
                    </mesh>
                </geometry>
                <material>
                    <diffuse>0 0 1 1</diffuse>
                    <script>
                        <name>Gazebo/Blue</name>
                        <uri>file://media/materials/scripts/gazebo.material</uri>
                    </script>
                </material>
                <cast_shadows>0</cast_shadows>
            </visual>
            <gravity>1</gravity>
            <velocity_decay />
        </link>
        <joint name="rotor_1_joint" type="revolute">
            <child>rotor_1</child>
            <parent>base_link</parent>
            <axis>
                <xyz>0 0 1</xyz>
                <limit>
                    <lower>-1e+16</lower>
                    <upper>1e+16</upper>
                </limit>
                <dynamics>
                    <spring_reference>0</spring_reference>
                    <spring_stiffness>0</spring_stiffness>
                </dynamics>
                <use_parent_model_frame>1</use_parent_model_frame>
            </axis>
        </joint>
        <link name="rotor_2">
            <pose frame="">0.09 0.09 -0.005 0 0 0</pose>
            <inertial>
                <pose frame="">0 0 0 0 -0 0</pose>
                <mass>0.005</mass>
                <inertia>
                    <ixx>9.75e-07</ixx>
                    <ixy>0</ixy>
                    <ixz>0</ixz>
                    <iyy>8.13545e-05</iyy>
                    <iyz>0</iyz>
                    <izz>8.22545e-05</izz>
                </inertia>
            </inertial>
            <collision name="rotor_2_collision">
                <pose frame="">0 0 0 0 -0 0</pose>
                <geometry>
                    <cylinder>
                        <length>0.005</length>
                        <radius>0.06</radius>
                    </cylinder>
                </geometry>
                <surface>
                    <contact>
                        <ode />
                    </contact>
                    <friction>
                        <ode />
                    </friction>
                </surface>
            </collision>
            <visual name="rotor_2_visual">
                <pose frame="">0 0 0 0 -0 0</pose>
                <geometry>
                    <mesh>
                        <scale>1 1 1</scale>
                        <uri>meshes/propeller_cw.dae</uri>
                    </mesh>
                </geometry>
                <material>
                    <diffuse>1 0 0 1</diffuse>
                    <script>
                        <name>Gazebo/Red</name>
                        <uri>file://media/materials/scripts/gazebo.material</uri>
                    </script>
                </material>
                <cast_shadows>0</cast_shadows>
            </visual>
            <gravity>1</gravity>
            <velocity_decay />
        </link>
        <joint name="rotor_2_joint" type="revolute">
            <child>rotor_2</child>
            <parent>base_link</parent>
            <axis>
                <xyz>0 0 1</xyz>
                <limit>
                    <lower>-1e+16</lower>
                    <upper>1e+16</upper>
                </limit>
                <dynamics>
                    <spring_reference>0</spring_reference>
                    <spring_stiffness>0</spring_stiffness>
                </dynamics>
                <use_parent_model_frame>1</use_parent_model_frame>
            </axis>
        </joint>
        <link name="rotor_3">
            <pose frame="">-0.09 -0.09 0.045 0 0 0</pose>
            <inertial>
                <pose frame="">0 0 0 0 -0 0</pose>
                <mass>0.005</mass>
                <inertia>
                    <ixx>9.75e-07</ixx>
                    <ixy>0</ixy>
                    <ixz>0</ixz>
                    <iyy>8.13545e-05</iyy>
                    <iyz>0</iyz>
                    <izz>8.22545e-05</izz>
                </inertia>
            </inertial>
            <collision name="rotor_3_collision">
                <pose frame="">0 0 0 0 -0 0</pose>
                <geometry>
                    <cylinder>
                        <length>0.005</length>
                        <radius>0.06</radius>
                    </cylinder>
                </geometry>
                <surface>
                    <contact>
                        <ode />
                    </contact>
                    <friction>
                        <ode />
                    </friction>
                </surface>
            </collision>
            <visual name="rotor_3_visual">
                <pose frame="">0 0 0 0 -0 0</pose>
                <geometry>
                    <mesh>
                        <scale>1 1 1</scale>
                        <uri>meshes/propeller_cw.dae</uri>
                    </mesh>
                </geometry>
                <material>
                    <diffuse>0 0 1 1</diffuse>
                    <script>
                        <name>Gazebo/Blue</name>
                        <uri>file://media/materials/scripts/gazebo.material</uri>
                    </script>
                </material>
                <cast_shadows>0</cast_shadows>
            </visual>
            <gravity>1</gravity>
            <velocity_decay />
        </link>
        <joint name="rotor_3_joint" type="revolute">
            <child>rotor_3</child>
            <parent>base_link</parent>
            <axis>
                <xyz>0 0 1</xyz>
                <limit>
                    <lower>-1e+16</lower>
                    <upper>1e+16</upper>
                </limit>
                <dynamics>
                    <spring_reference>0</spring_reference>
                    <spring_stiffness>0</spring_stiffness>
                </dynamics>
                <use_parent_model_frame>1</use_parent_model_frame>
            </axis>
        </joint>

        <plugin filename="libignition-gazebo-pose-publisher-system.so" name="ignition::gazebo::systems::PosePublisher">
            <publish_link_pose>true</publish_link_pose>
            <publish_sensor_pose>true</publish_sensor_pose>
            <publish_collision_pose>false</publish_collision_pose>
            <publish_visual_pose>false</publish_visual_pose>
            <publish_nested_model_pose>true</publish_nested_model_pose>
            <use_pose_vector_msg>true</use_pose_vector_msg>
            <static_publisher>true</static_publisher>
            <static_update_frequency>60</static_update_frequency>
        </plugin>

        <plugin filename="libignition-gazebo-pose-publisher-system.so" name="ignition::gazebo::systems::PosePublisher">
            <publish_link_pose>false</publish_link_pose>
            <publish_sensor_pose>false</publish_sensor_pose>
            <publish_collision_pose>false</publish_collision_pose>
            <publish_visual_pose>false</publish_visual_pose>
            <publish_nested_model_pose>false</publish_nested_model_pose>
            <use_pose_vector_msg>true</use_pose_vector_msg>
            <static_publisher>false</static_publisher>
        </plugin>

        <plugin filename="libignition-gazebo-pose-publisher-system.so"
          name="ignition::gazebo::systems::PosePublisher">
          <publish_link_pose>false</publish_link_pose>
          <publish_sensor_pose>true</publish_sensor_pose>
          <publish_collision_pose>false</publish_collision_pose>
          <publish_visual_pose>false</publish_visual_pose>
          <publish_nested_model_pose>false</publish_nested_model_pose>
          <use_pose_vector_msg>true</use_pose_vector_msg>
          <static_publisher>true</static_publisher>
          <static_update_frequency>200</static_update_frequency>
        </plugin>
        <plugin filename="libignition-gazebo-pose-publisher-system.so"
          name="ignition::gazebo::systems::PosePublisher">
          <publish_link_pose>true</publish_link_pose>
          <publish_sensor_pose>false</publish_sensor_pose>
          <publish_collision_pose>false</publish_collision_pose>
          <publish_visual_pose>false</publish_visual_pose>
          <publish_nested_model_pose>true</publish_nested_model_pose>
          <use_pose_vector_msg>true</use_pose_vector_msg>
          <static_publisher>false</static_publisher>
        </plugin>

        <plugin filename="libignition-gazebo-odometry-publisher-system.so"
          name="ignition::gazebo::systems::OdometryPublisher">
					<dimensions>3</dimensions>
        </plugin>

        <plugin filename="libignition-gazebo-multicopter-motor-model-system.so" name="ignition::gazebo::systems::MulticopterMotorModel">
            <robotNamespace>model/rmf_owl</robotNamespace>
            <jointName>rotor_0_joint</jointName>
            <linkName>rotor_0</linkName>
            <turningDirection>ccw</turningDirection>
            <timeConstantUp>0.0182</timeConstantUp>
            <timeConstantDown>0.0182</timeConstantDown>
            <maxRotVelocity>1000.0</maxRotVelocity>
            <motorConstant>0.02246</motorConstant>
            <momentConstant>0.016754</momentConstant>
            <commandSubTopic>command/motor_speed</commandSubTopic>
            <motorNumber>0</motorNumber>
            <rotorDragCoefficient>2.0673e-04</rotorDragCoefficient>
            <rollingMomentCoefficient>0</rollingMomentCoefficient>
            <motorSpeedPubTopic>motor_speed/0</motorSpeedPubTopic>
            <rotorVelocitySlowdownSim>0.5</rotorVelocitySlowdownSim>
            <motorType>velocity</motorType>
        </plugin>

        <plugin filename="libignition-gazebo-multicopter-motor-model-system.so" name="ignition::gazebo::systems::MulticopterMotorModel">
            <robotNamespace>model/rmf_owl</robotNamespace>
            <jointName>rotor_1_joint</jointName>
            <linkName>rotor_1</linkName>
            <turningDirection>ccw</turningDirection>
            <timeConstantUp>0.0182</timeConstantUp>
            <timeConstantDown>0.0182</timeConstantDown>
            <maxRotVelocity>1000.0</maxRotVelocity>
            <motorConstant>0.02246</motorConstant>
            <momentConstant>0.016754</momentConstant>
            <commandSubTopic>command/motor_speed</commandSubTopic>
            <motorNumber>1</motorNumber>
            <rotorDragCoefficient>2.0673e-04</rotorDragCoefficient>
            <rollingMomentCoefficient>0</rollingMomentCoefficient>
            <motorSpeedPubTopic>motor_speed/1</motorSpeedPubTopic>
            <rotorVelocitySlowdownSim>0.5</rotorVelocitySlowdownSim>
            <motorType>velocity</motorType>
        </plugin>
        <plugin filename="libignition-gazebo-multicopter-motor-model-system.so" name="ignition::gazebo::systems::MulticopterMotorModel">
            <robotNamespace>model/rmf_owl</robotNamespace>
            <jointName>rotor_2_joint</jointName>
            <linkName>rotor_2</linkName>
            <turningDirection>cw</turningDirection>
            <timeConstantUp>0.0182</timeConstantUp>
            <timeConstantDown>0.0182</timeConstantDown>
            <maxRotVelocity>1000.0</maxRotVelocity>
            <motorConstant>0.02246</motorConstant>
            <momentConstant>0.016754</momentConstant>
            <commandSubTopic>command/motor_speed</commandSubTopic>
            <motorNumber>2</motorNumber>
            <rotorDragCoefficient>2.0673e-04</rotorDragCoefficient>
            <rollingMomentCoefficient>0</rollingMomentCoefficient>
            <motorSpeedPubTopic>motor_speed/2</motorSpeedPubTopic>
            <rotorVelocitySlowdownSim>0.5</rotorVelocitySlowdownSim>
            <motorType>velocity</motorType>
        </plugin>
        <plugin filename="libignition-gazebo-multicopter-motor-model-system.so" name="ignition::gazebo::systems::MulticopterMotorModel">
            <robotNamespace>model/rmf_owl</robotNamespace>
            <jointName>rotor_3_joint</jointName>
            <linkName>rotor_3</linkName>
            <turningDirection>cw</turningDirection>
            <timeConstantUp>0.0182</timeConstantUp>
            <timeConstantDown>0.0182</timeConstantDown>
            <maxRotVelocity>1000.0</maxRotVelocity>
            <motorConstant>0.02246</motorConstant>
            <momentConstant>0.016754</momentConstant>
            <commandSubTopic>command/motor_speed</commandSubTopic>
            <motorNumber>3</motorNumber>
            <rotorDragCoefficient>2.0673e-04</rotorDragCoefficient>
            <rollingMomentCoefficient>0</rollingMomentCoefficient>
            <motorSpeedPubTopic>motor_speed/3</motorSpeedPubTopic>
            <rotorVelocitySlowdownSim>0.5</rotorVelocitySlowdownSim>
            <motorType>velocity</motorType>
        </plugin>
        <plugin filename="libignition-gazebo-multicopter-control-system.so" name="ignition::gazebo::systems::MulticopterVelocityControl">
            <robotNamespace>model/rmf_owl</robotNamespace>
            <commandSubTopic>cmd_vel</commandSubTopic>
            <motorControlPubTopic>command/motor_speed</motorControlPubTopic>
            <enableSubTopic>velocity_controller/enable</enableSubTopic>
            <comLinkName>base_link</comLinkName>
            <velocityGain>6 6 10</velocityGain>
            <attitudeGain>4 4 2</attitudeGain>
            <angularRateGain>0.7 0.7 0.7</angularRateGain>
            <maximumLinearAcceleration>4 4 5</maximumLinearAcceleration>
            <maximumLinearVelocity>3 3 1.8</maximumLinearVelocity>
            <maximumAngularVelocity>3 3 1.9</maximumAngularVelocity>
            <linearVelocityNoiseMean>0 0 0</linearVelocityNoiseMean>
            <!-- linearVelocityNoiseStdDev based on error values reported in the paper Shen et. al., -->
            <!-- Vision-Based State Estimation and Trajectory Control Towards High-Speed Flight with a Quadrotor -->
            <!-- http://citeseerx.ist.psu.edu/viewdoc/download?doi=10.1.1.490.7958&rep=rep1&type=pdf -->
            <!--<linearVelocityNoiseStdDev>0.1105 0.1261 0.0947</linearVelocityNoiseStdDev>-->
            <linearVelocityNoiseStdDev>0.01 0.01 0.01</linearVelocityNoiseStdDev>
            <angularVelocityNoiseMean>0 0 0</angularVelocityNoiseMean>
            <!-- angularVelocityNoiseStdDev values based on ADIS16448's Rate Noise Density with a sample  -->
            <!-- time of 0.004 ms. -->
            <angularVelocityNoiseStdDev>0.004 0.004 0.004</angularVelocityNoiseStdDev>

            <rotorConfiguration>
                <rotor>
                    <jointName>rotor_0_joint</jointName>
                    <forceConstant>0.02246</forceConstant>
                    <momentConstant>1.6754e-2</momentConstant>
                    <direction>1</direction>
                </rotor>
                <rotor>
                    <jointName>rotor_1_joint</jointName>
                    <forceConstant>0.02246</forceConstant>
                    <momentConstant>1.6754e-2</momentConstant>
                    <direction>1</direction>
                </rotor>
                <rotor>
                    <jointName>rotor_2_joint</jointName>
                    <forceConstant>0.02246</forceConstant>
                    <momentConstant>1.6754e-2</momentConstant>
                    <direction>-1</direction>
                </rotor>
                <rotor>
                    <jointName>rotor_3_joint</jointName>
                    <forceConstant>0.02246</forceConstant>
                    <momentConstant>1.6754e-2</momentConstant>
                    <direction>-1</direction>
                </rotor>
            </rotorConfiguration>
        </plugin>
    </model>
</sdf>
